<mujoco model="lz_gripper">
  <compiler angle="radian" />
  <asset>
    <mesh name="base_link" content_type="model/stl" file="./lz_gripper/meshes/base_link.STL" />
    <mesh name="thumb_link1" content_type="model/stl" file="./lz_gripper/meshes/thumb_link1.STL" />
    <mesh name="thumb_link2" content_type="model/stl" file="./lz_gripper/meshes/thumb_link2.STL" />
    <mesh name="thumb_link3" content_type="model/stl" file="./lz_gripper/meshes/thumb_link3.STL" />
    <mesh name="index_link1" content_type="model/stl" file="./lz_gripper/meshes/index_link1.STL" />
    <mesh name="index_link2" content_type="model/stl" file="./lz_gripper/meshes/index_link2.STL" />
    <mesh name="middle_link1" content_type="model/stl" file="./lz_gripper/meshes/middle_link1.STL" />
    <mesh name="middle_link2" content_type="model/stl" file="./lz_gripper/meshes/middle_link2.STL" />
    <mesh name="ring_link1" content_type="model/stl" file="./lz_gripper/meshes/ring_link1.STL" />
    <mesh name="ring_link2" content_type="model/stl" file="./lz_gripper/meshes/ring_link2.STL" />
    <mesh name="little_link1" content_type="model/stl" file="./lz_gripper/meshes/little_link1.STL" />
    <mesh name="little_link2" content_type="model/stl" file="./lz_gripper/meshes/little_link2.STL" />
    <mesh name="allegro_tip" content_type="model/obj" file="./lz_gripper/meshes/allegro_tip.obj" scale="0.8 0.6 0.8" />
    <mesh name="allegro_thumb_tip" content_type="model/obj" file="./lz_gripper/meshes/allegro_thumb_tip.obj" scale="0.8 0.6 0.8" />
    </asset>
  <worldbody>
    <body name="base" gravcomp="1">
      <body name="base_link" gravcomp="1">
        <inertial pos="-0.0094603 -0.088524 0.0020382" quat="0.00480245 0.698144 0.0700049 0.712511" mass="0.37668" diaginertia="0.00042673 0.000310173 0.000261927" />
        <geom type="mesh" contype="0" conaffinity="0" group="1" density="0" rgba="0.89804 0.92157 0.92941 1" mesh="base_link" class="plastic_visual" />
        <geom type="mesh" rgba="0.89804 0.92157 0.92941 1" mesh="base_link" class="plastic_collision" />
        <body name="thumb_link1" pos="0.023 -0.0245 -0.04835" quat="1.34924e-11 -3.67321e-06 -1 3.67321e-06" gravcomp="1">
          <inertial pos="-0.00017965 6.8304e-06 0.018159" quat="0.653318 -0.259727 -0.267639 0.658853" mass="0.0099033" diaginertia="1.05839e-06 6.84654e-07 5.60295e-07" />
          <joint name="thumb_joint1" pos="0 0 0" axis="0 0 1" range="0 2.14" class="hand_joint" />
          <geom type="mesh" contype="0" conaffinity="0" group="1" density="0" rgba="0.89804 0.92157 0.92941 1" mesh="thumb_link1" class="plastic_visual" />
          <geom type="mesh" rgba="0.89804 0.92157 0.92941 1" mesh="thumb_link1" class="plastic_collision" />
          <body name="thumb_link2" pos="-0.0088613 0.0060912 0.01565" quat="0.707077 -0.707079 -0.00637732 0.0063773" gravcomp="1">
            <inertial pos="-0.020501 0.0067015 -0.0064038" quat="0.112531 0.698399 -0.11085 0.69806" mass="0.014226" diaginertia="2.8832e-06 2.6148e-06 4.7418e-07" />
            <joint name="thumb_joint2" pos="0 0 0" axis="0 0 -1" range="0 0.35" class="hand_joint" />
            <geom type="mesh" contype="0" conaffinity="0" group="1" density="0" rgba="0.89804 0.92157 0.92941 1" mesh="thumb_link2" class="plastic_visual" />
            <geom type="mesh" rgba="0.89804 0.92157 0.92941 1" mesh="thumb_link2" class="plastic_collision" />
            <body name="thumb_link3" pos="-0.042286 0.015391 -0.01415" quat="0.984807 0 0 -0.17365" gravcomp="1">
              <inertial pos="-0.0196681 -0.000581972 0.00789994" quat="0.503484 0.50348 0.496491 0.496495" mass="0.00784968" diaginertia="1.53732e-06 1.36362e-06 2.8083e-07" />
              <joint name="thumb_joint3" pos="0 0 0" axis="0 0 -1" range="0 1.57" class="hand_joint" />
              <geom type="mesh" contype="0" conaffinity="0" group="1" density="0" rgba="0.898039 0.921569 0.929412 1" mesh="thumb_link3" class="plastic_visual" />
              <geom type="mesh" rgba="0.898039 0.921569 0.929412 1" mesh="thumb_link3" class="plastic_collision" />
              <body name="thumb_tip" pos="-0.04 0 0.008" gravcomp="1">
                <geom pos="0.004 0 0" quat="0.707105 0 -0.707108 0" type="mesh" contype="0" conaffinity="0" group="1" density="0" rgba="0.9 0.9 0.9 1" mesh="allegro_thumb_tip" class="plastic_visual" />
                </body>
              </body>
            </body>
          </body>
        <body name="index_link1" pos="0.031418 0 -0.0053197" quat="0.694662 -9.06333e-08 0.719336 -9.06333e-08" gravcomp="1">
          <inertial pos="-0.0215645 0.000393824 -0.00874621" quat="0.00685726 0.707054 -0.00514381 0.707108" mass="0.0142262" diaginertia="2.88325e-06 2.61484e-06 4.7418e-07" />
          <joint name="index_joint1" pos="0 0 0" axis="0 0 1" range="0 1.57" class="hand_joint" />
          <geom type="mesh" contype="0" conaffinity="0" group="1" density="0" rgba="0.898039 0.921569 0.929412 1" mesh="index_link1" class="plastic_visual" />
          <geom type="mesh" rgba="0.898039 0.921569 0.929412 1" mesh="index_link1" class="plastic_collision" />
          <body name="index_link2" pos="-0.044995 -0.00066876 -0.001" gravcomp="1">
            <inertial pos="-0.019676 -6.2395e-05 -0.0079" quat="0.488182 0.488185 0.511545 0.511542" mass="0.0078496" diaginertia="1.53734e-06 1.3636e-06 2.80829e-07" />
            <joint name="index_joint2" pos="0 0 0" axis="0 0 1" range="0 1.57" class="hand_joint" />
            <geom type="mesh" contype="0" conaffinity="0" group="1" density="0" rgba="0.89804 0.92157 0.92941 1" mesh="index_link2" class="plastic_visual" />
            <geom type="mesh" rgba="0.89804 0.92157 0.92941 1" mesh="index_link2" class="plastic_collision" />
            <body name="index_tip" pos="-0.04 0 -0.008" gravcomp="1">
              <geom pos="0.004 -0.001 0" quat="0.707105 0 -0.707108 0" type="mesh" contype="0" conaffinity="0" group="1" density="0" rgba="0.9 0.9 0.9 1" mesh="allegro_tip" class="plastic_visual" />
              </body>
            </body>
          </body>
        <body name="middle_link1" pos="0.0089 0 0" quat="0.707105 0 0.707108 0" gravcomp="1">
          <inertial pos="-0.0215563 0.000714277 -0.0087462" quat="0.0121111 0.706996 -0.0103989 0.707037" mass="0.0142262" diaginertia="2.88325e-06 2.61484e-06 4.7418e-07" />
          <joint name="middle_joint1" pos="0 0 0" axis="0 0 1" range="0 1.57" class="hand_joint" />
          <geom type="mesh" contype="0" conaffinity="0" group="1" density="0" rgba="0.898039 0.921569 0.929412 1" mesh="middle_link1" class="plastic_visual" />
          <geom type="mesh" rgba="0.898039 0.921569 0.929412 1" mesh="middle_link1" class="plastic_collision" />
          <body name="middle_link2" pos="-0.045 0 -0.001" quat="0.707105 0 0 0.707108" gravcomp="1">
            <inertial pos="-0.0196681 0.000581963 -0.00789994" quat="0.496491 0.496496 0.503484 0.50348" mass="0.00784968" diaginertia="1.53732e-06 1.36362e-06 2.80831e-07" />
            <joint name="middle_joint2" pos="0 0 0" axis="0 0 1" range="0 1.57" class="hand_joint" />
            <geom type="mesh" contype="0" conaffinity="0" group="1" density="0" rgba="0.898039 0.921569 0.929412 1" mesh="middle_link2" class="plastic_visual" />
            <geom type="mesh" rgba="0.898039 0.921569 0.929412 1" mesh="middle_link2" class="plastic_collision" />
            <body name="middle_tip" pos="0 0.04 -0.008" quat="0.707105 0 0 -0.707108" gravcomp="1">
              <geom pos="0.004 -0.001 0" quat="0.707105 0 -0.707108 0" type="mesh" contype="0" conaffinity="0" group="1" density="0" rgba="0.9 0.9 0.9 1" mesh="allegro_tip" class="plastic_visual" />
              </body>
            </body>
          </body>
        <body name="ring_link1" pos="-0.013629 0 -0.0046985" quat="0.719336 0 0.694662 0" gravcomp="1">
          <inertial pos="-0.0215563 0.000714277 -0.0087462" quat="0.0121108 0.706996 -0.0103989 0.707037" mass="0.0142262" diaginertia="2.88325e-06 2.61485e-06 4.7418e-07" />
          <joint name="ring_joint1" pos="0 0 0" axis="0 0 1" range="0 1.57" class="hand_joint" />
          <geom type="mesh" contype="0" conaffinity="0" group="1" density="0" rgba="0.898039 0.921569 0.929412 1" mesh="ring_link1" class="plastic_visual" />
          <geom type="mesh" rgba="0.898039 0.921569 0.929412 1" mesh="ring_link1" class="plastic_collision" />
          <body name="ring_link2" pos="-0.045 0 -0.001" gravcomp="1">
            <inertial pos="-0.019668 0.000581976 -0.00789991" quat="0.496489 0.4965 0.503482 0.503481" mass="0.00784963" diaginertia="1.5373e-06 1.3636e-06 2.80829e-07" />
            <joint name="ring_joint2" pos="0 0 0" axis="0 0 1" range="0 1.57" class="hand_joint" />
            <geom type="mesh" contype="0" conaffinity="0" group="1" density="0" rgba="0.898039 0.921569 0.929412 1" mesh="ring_link2" class="plastic_visual" />
            <geom type="mesh" rgba="0.898039 0.921569 0.929412 1" mesh="ring_link2" class="plastic_collision" />
            <body name="ring_tip" pos="-0.04 0 -0.008" gravcomp="1">
              <geom pos="0.004 -0.001 0" quat="0.707105 0 -0.707108 0" type="mesh" contype="0" conaffinity="0" group="1" density="0" rgba="0.9 0.9 0.9 1" mesh="allegro_tip" class="plastic_visual" />
              </body>
            </body>
          </body>
        <body name="little_link1" pos="-0.036007 0 -0.0094157" quat="0.731348 0 0.682005 0" gravcomp="1">
          <inertial pos="-0.0215645 0.000393824 -0.00874621" quat="0.00685726 0.707054 -0.00514381 0.707108" mass="0.0142262" diaginertia="2.88325e-06 2.61484e-06 4.7418e-07" />
          <joint name="little_joint1" pos="0 0 0" axis="0 0 1" range="0 1.57" class="hand_joint" />
          <geom type="mesh" contype="0" conaffinity="0" group="1" density="0" rgba="1 1 1 1" mesh="little_link1" class="plastic_visual" />
          <geom type="mesh" rgba="1 1 1 1" mesh="little_link1" class="plastic_collision" />
          <body name="little_link2" pos="-0.045 0 -0.001" gravcomp="1">
            <inertial pos="-0.019668 0.000581972 -0.00789991" quat="0.496489 0.496499 0.503482 0.503481" mass="0.00784963" diaginertia="1.5373e-06 1.3636e-06 2.80829e-07" />
            <joint name="little_joint2" pos="0 0 0" axis="0 0 1" range="0 1.57" class="hand_joint" />
            <geom type="mesh" contype="0" conaffinity="0" group="1" density="0" rgba="0.898039 0.921569 0.929412 1" mesh="little_link2" class="plastic_visual" />
            <geom type="mesh" rgba="0.898039 0.921569 0.929412 1" mesh="little_link2" class="plastic_collision" />
            <body name="little_tip" pos="-0.04 0 -0.008" gravcomp="1">
              <geom pos="0.004 -0.001 0" quat="0.707105 0 -0.707108 0" type="mesh" contype="0" conaffinity="0" group="1" density="0" rgba="0.9 0.9 0.9 1" mesh="allegro_tip" class="plastic_visual" />
              </body>
            </body>
          </body>
        </body>
      </body>
    </worldbody>
  </mujoco>
